Workbook

Sheet 1.ภาพรวม
A1: TH-EVI : โมเดลประมาณการความต้องการสถานีชาร์จ EV ของไทย
A2: Thailand EV Infrastructure Projection Model • แรงบันดาลใจจาก NREL EVI-Pro • นำร่องจังหวัดเชียงใหม่
B4: โมเดลนี้คืออะไร
B5: TH-EVI ประเมินความต้องการชาร์จ EV ต่อวันโดยใช้ข้อมูลไทยที่ตรวจสอบได้: DOPA 2568, DLT เม.ย. 2569 และ AADT กรมทางหลวง 2566. v4 ปรับ adoption table ให้ใช้ DLT BEV+PHEV สะสมของเชียงใหม่ 15,229 คันเป็น seed ปี 2026 แทนการอาศัย legacy placeholder
B8: โครงสร้าง 4 ชั้น (Layer) ของโมเดล
B9: ชั้น | C9: หน้าที่ | D9: อินพุตหลัก | E9: ผลลัพธ์
B10: 1. Adoption | C10: พยากรณ์สัดส่วน BEV ในรถใหม่ด้วย S-curve (logistic) | D10: ข้อมูล FTI ปี 2566-2568 | E10: % BEV รายปี + EV สะสมในจังหวัด
B11: 2. Demand | C11: แปลงปริมาณจราจร/ประชากร EV เป็นครั้งชาร์จ/วัน | D11: AADT, ประชากร EV, prob.ชาร์จ | E11: จำนวนครั้งที่ชาร์จ/วัน, kWh/วัน
B12: 3. Site | C12: ปรับด้วยทำเล การมองเห็น สถานีคู่แข่ง | D12: คะแนนทำเล, คู่แข่งรอบข้าง | E12: ส่วนแบ่งตลาดที่สถานีแย่งได้จริง
B13: 4. Temporal | C13: กระจายรายชั่วโมง + คิวด้วย Erlang-C | D13: รูปแบบการมาแต่ละชั่วโมง | E13: จำนวนหัวชาร์จที่ต้องมี
B15: สูตรแกนกลาง
B16: ความต้องการพื้นที่: EV visits/วัน = AADT × สัดส่วน EV ในกลุ่มรถ(ปี) × ความน่าจะเป็นที่รถจะมาชาร์จ
B17: ความต้องการสถานี: จำนวนครั้งที่ชาร์จ/วัน = (ผู้อยู่อาศัย + แอพเรียกรถ + นักท่องเที่ยว + ขนส่ง) × calibration factor โดย calibration factor ปัจจุบันเป็น temporary anchor จากข้อมูลสถานี 1 จุดที่ยังต้องยืนยัน
B19: ความน่าเชื่อถือโดยสรุป (รายละเอียดในชีต '5.Validation')
B20: ตัวชี้วัด | C20: ค่า | D20: หมายเหตุ
B21: Adoption MAPE | C21: 8.5% | D21: เทียบ S-curve กับยอด BEV จริงของ FTI ปี 2566-2568
B22: Adoption RMSE | C22: 1.49 pp | D22: คลาดเคลื่อนเฉลี่ยระดับจุดเปอร์เซ็นต์
B23: Station calibration | C23: 0.409 base; sensitivity 0.629/0.943 | D23: rebased หลังใช้ DLT stock seed; ยังเป็น temporary เพราะ anchor สถานียังเป็น verbal/operator-reported
B24: สถานะ validation สถานี | C24: Just-identified | D24: ต้องเก็บอีก ≥4 สถานีจึงประเมิน out-of-sample ได้

Sheet 2.สมมติฐาน
A1: สมมติฐานทั้งหมด
A2: ช่องพื้นหลังเหลือง/ครีม = อินพุตที่ปรับได้ (เลขสีน้ำเงิน) • ชีตอื่นอ้างอิงค่ามาจากที่นี่ทั้งหมด
B4: พารามิเตอร์ | C4: ค่า | D4: หน่วย | E4: แหล่งที่มา / เหตุผล
B5: A. พารามิเตอร์ S-curve การยอมรับ EV (logistic)
B6: เพดานสูงสุด (carrying capacity) | C6: 0.85 | D6: สัดส่วน | E6: สมมติ BEV ถึง 85% ของรถใหม่เมื่ออิ่มตัว (อิง 30@30 + แนวโน้มโลก)
B7: อัตราการเติบโต (growth rate) | C7: 0.179 | D7: ต่อปี | E7: ปรับด้วย scipy least-squares กับข้อมูล FTI รายปี 2566-2568
B8: ปีกึ่งกลาง (midpoint 50%) | C8: 2032 | D8: ค.ศ. | E8: ปีที่ถึง 50% ของเพดาน — สอดคล้องเป้า 30@30 (2030≈35%)
B9: ตัวปรับระดับจังหวัด (เชียงใหม่) | C9: 1 | D9: x | E9: ใช้ฐาน ร.1 ระดับชาติโดยตรง (แก้ denominator ผสมเดิม 0.40)
B11: B. พารามิเตอร์กองรถจังหวัดเชียงใหม่ (ใช้ DLT stock เป็นจุดตั้งต้นปี 2026)
B12: ฐานรถใหม่ ร.1 ต่อปีของ S-curve เดิม (legacy placeholder) | C12: 6200 | D12: คัน/ปี | E12: คงไว้เพื่ออธิบายสูตร new-BEV รายปีเท่านั้น; ไม่ใช่ BEV สะสม และไม่ใช้แทนค่า DLT stock
B13: ขนาดกลุ่มรถยนต์นั่งรวม รย.1 | C13: 453310 | D13: คัน | E13: Verified DLT 30 เม.ย. 2569; ใช้เป็น denominator ของ EV penetration
B14: อายุปลดระวางรถ (scrappage) | C14: 14 | D14: ปี | E14: ใช้ cohort retirement หลัง 14 ปีในโมเดลสาธิตนี้; หากต้องการความสมจริงควรเปลี่ยนเป็น gradual scrappage หรือใช้ทะเบียนสะสมจริง
B16: C. ความน่าจะเป็นที่จะชาร์จ ตามประเภททำเล
B17: ทางหลวง (highway) | C17: 0.06 | D17: สัดส่วน | E17: รถวิ่งผ่าน ส่วนน้อยแวะชาร์จด่วน
B18: ใจกลางเมือง (city center) | C18: 0.12 | D18: สัดส่วน | E18: ความหนาแน่นสูง แวะปานกลาง
B19: จุดหมายปลายทาง (destination) | C19: 0.2 | D19: สัดส่วน | E19: ห้าง/สนามบิน จอดนานโอกาสชาร์จสูง
B20: ชานเมือง (suburban) | C20: 0.08 | D20: สัดส่วน | E20: สมมติฐานนำร่อง
B22: D. สถานี ฉากทัศน์ Base
B23: สัดส่วนพึ่งชาร์จสาธารณะ | C23: 0.35 | D23: สัดส่วน | E23: ผู้ใช้ EV ที่ไม่มีที่ชาร์จบ้านเพียงพอ
B24: ครั้งชาร์จสาธารณะ/สัปดาห์ | C24: 1.5 | D24: ครั้ง | E24: พฤติกรรมผู้อยู่อาศัย
B25: capture ผู้อยู่อาศัย | C25: 0.2 | D25: สัดส่วน | E25: ส่วนแบ่งที่สถานีนี้แย่งได้
B26: คนขับแพลตฟอร์มเรียกรถในพื้นที่ | C26: 4000 | D26: คน | E26: ประมาณการ Grab/Bolt/In Driver เชียงใหม่
B27: สัดส่วน EV ในเรียกรถ | C27: 0.05 | D27: สัดส่วน | E27: ฐานปี 2026
B28: นักท่องเที่ยวมาถึง/วัน | C28: 33000 | D28: คน/วัน | E28: ประมาณการ ททท. เชียงใหม่
B29: calibration factor (base: 130 ÷ raw demand หลังใช้ DLT seed) | C29: 0.409 | D29: x | E29: คำนวณใหม่ใน v5: raw demand ปี 2026 หลังใช้ DLT seed ประมาณ 318 ครั้ง/วัน; base anchor 130 ครั้ง/วัน => factor 0.409. หากใช้ sensitivity 200/300 factor จะเป็น 0.629/0.943
B30: kWh เฉลี่ย/ครั้ง (สถานี) | C30: 32 | D30: kWh | E30: base case
B31: ครั้ง/หัวชาร์จ/วัน (ความจุ) | C31: 22 | D31: ครั้ง | E31: เพดานความจุต่อหัว
A34: E. Verified public data สำหรับ consultant review
A35: DOPA จังหวัดเชียงใหม่ | B35: 1798588 | C35: คน | D35: DOPA 2568 | E35: ครัวเรือน 916,688
A36: DLT รย.1 รถยนต์นั่งรวม | B36: 453310 | C36: คัน | D36: DLT 30 เม.ย. 2569 | E36: ใช้เป็น denominator ของ passenger-car EV share
A37: DLT รย.1 BEV | B37: 13089 | C37: คัน | D37: DLT 30 เม.ย. 2569 | E37: BEV share 2.89%
A38: DLT รย.1 PHEV | B38: 2140 | C38: คัน | D38: DLT 30 เม.ย. 2569 | E38: PHEV gasoline + PHEV diesel
A39: DLT รย.1 BEV+PHEV | B39: 15229 | C39: คัน | D39: DLT 30 เม.ย. 2569 | E39: chargeable share 3.36%
A40: DLT รถตามกฎหมายรถยนต์ BEV+PHEV | B40: 18189 | C40: คัน | D40: DLT 30 เม.ย. 2569 | E40: ใช้สำหรับภาพรวมจังหวัด ไม่ใช่เฉพาะ รย.1
A41: AADT Route 1141 ดอนจั่น-เชียงใหม่ | B41: 118853 | C41: คัน/วัน | D41: DOH AADT 2566 | E41: จุดสำรวจ 7+000
A42: Model treatment v4 | B42: ใช้ DLT BEV+PHEV สะสมเป็น seed ของปี 2026 | C42: 15229 | D42: คัน | E42: แทนการปล่อยให้ตารางสะสมจาก legacy placeholder 6,200 ซึ่งทำให้ stock ต่ำกว่าค่าจริง
A43: AADT Route 11 อุโมงค์-รินคำ | B43: 69988 | C43: คัน/วัน | D43: DOH AADT 2566 | E43: จุดสำรวจ 543+850
A44: Station calibration sensitivity v5 | B44: Anchor | C44: Raw demand | D44: Calibration factor | E44: ผลหลัง calibration
A45: Conservative verbal anchor | B45: 130 | C45: 318 | D45: 0.409 | E45: 130
A46: Confident sensitivity | B46: 200 | C46: 318 | D46: 0.629 | E46: 200
...

Sheet 3.S-curve การยอมรับ
A1: ชั้นที่ 1 : S-curve การยอมรับ EV (logistic)
B2: สูตร: สัดส่วน BEV รถใหม่ = เพดาน ÷ (1+EXP(-growth×(ปี-midpoint))) × ตัวปรับจังหวัด. v4 ใช้ DLT เม.ย. 2569 เป็น calibration seed: รย.1 BEV 13,089 + PHEV 2,140 = 15,229 คัน สำหรับ EV สะสมปี 2026 แล้ว forecast ต่อจากจุดนี้
B4: ปี | C4: สัดส่วน BEV รถใหม่ | D4: BEV ใหม่/ปีจาก S-curve (คัน) | E4: ปลดระวาง/ปี (คัน) | F4: EV สะสมในกลุ่มรถ / DLT-seeded stock | G4: สัดส่วน EV ในกลุ่มรถ | H4: สถานะข้อมูล
B5: 2018 | C5: =MIN('2.สมมติฐาน'!$C$6/(1+EXP(-'2.สมมติฐาน'!$C$7*(2018-'2.สมมติฐาน'!$C$8)))*'2.สมมติฐาน'!$C$9,'2.สมมติฐาน'!$C$6) | D5: ='2.สมมติฐาน'!$C$12*C5 | E5: 0 | F5: =MAX(D5-E5,0) | G5: =F5/'2.สมมติฐาน'!$C$13 | H5: ย้อนหลังก่อน seed; ใช้ดูแนวโน้มเท่านั้น
B6: 2019 | C6: =MIN('2.สมมติฐาน'!$C$6/(1+EXP(-'2.สมมติฐาน'!$C$7*(2019-'2.สมมติฐาน'!$C$8)))*'2.สมมติฐาน'!$C$9,'2.สมมติฐาน'!$C$6) | D6: ='2.สมมติฐาน'!$C$12*C6 | E6: 0 | F6: =MAX(F5+D6-E6,0) | G6: =F6/'2.สมมติฐาน'!$C$13 | H6: ย้อนหลังก่อน seed; ใช้ดูแนวโน้มเท่านั้น
B7: 2020 | C7: =MIN('2.สมมติฐาน'!$C$6/(1+EXP(-'2.สมมติฐาน'!$C$7*(2020-'2.สมมติฐาน'!$C$8)))*'2.สมมติฐาน'!$C$9,'2.สมมติฐาน'!$C$6) | D7: ='2.สมมติฐาน'!$C$12*C7 | E7: 0 | F7: =MAX(F6+D7-E7,0) | G7: =F7/'2.สมมติฐาน'!$C$13 | H7: ย้อนหลังก่อน seed; ใช้ดูแนวโน้มเท่านั้น
B8: 2021 | C8: =MIN('2.สมมติฐาน'!$C$6/(1+EXP(-'2.สมมติฐาน'!$C$7*(2021-'2.สมมติฐาน'!$C$8)))*'2.สมมติฐาน'!$C$9,'2.สมมติฐาน'!$C$6) | D8: ='2.สมมติฐาน'!$C$12*C8 | E8: 0 | F8: =MAX(F7+D8-E8,0) | G8: =F8/'2.สมมติฐาน'!$C$13 | H8: ย้อนหลังก่อน seed; ใช้ดูแนวโน้มเท่านั้น
B9: 2022 | C9: =MIN('2.สมมติฐาน'!$C$6/(1+EXP(-'2.สมมติฐาน'!$C$7*(2022-'2.สมมติฐาน'!$C$8)))*'2.สมมติฐาน'!$C$9,'2.สมมติฐาน'!$C$6) | D9: ='2.สมมติฐาน'!$C$12*C9 | E9: 0 | F9: =MAX(F8+D9-E9,0) | G9: =F9/'2.สมมติฐาน'!$C$13 | H9: ย้อนหลังก่อน seed; ใช้ดูแนวโน้มเท่านั้น
B10: 2023 | C10: =MIN('2.สมมติฐาน'!$C$6/(1+EXP(-'2.สมมติฐาน'!$C$7*(2023-'2.สมมติฐาน'!$C$8)))*'2.สมมติฐาน'!$C$9,'2.สมมติฐาน'!$C$6) | D10: ='2.สมมติฐาน'!$C$12*C10 | E10: 0 | F10: =MAX(F9+D10-E10,0) | G10: =F10/'2.สมมติฐาน'!$C$13 | H10: ย้อนหลังก่อน seed; ใช้ดูแนวโน้มเท่านั้น
B11: 2024 | C11: =MIN('2.สมมติฐาน'!$C$6/(1+EXP(-'2.สมมติฐาน'!$C$7*(2024-'2.สมมติฐาน'!$C$8)))*'2.สมมติฐาน'!$C$9,'2.สมมติฐาน'!$C$6) | D11: ='2.สมมติฐาน'!$C$12*C11 | E11: 0 | F11: =MAX(F10+D11-E11,0) | G11: =F11/'2.สมมติฐาน'!$C$13 | H11: ย้อนหลังก่อน seed; ใช้ดูแนวโน้มเท่านั้น
B12: 2025 | C12: =MIN('2.สมมติฐาน'!$C$6/(1+EXP(-'2.สมมติฐาน'!$C$7*(2025-'2.สมมติฐาน'!$C$8)))*'2.สมมติฐาน'!$C$9,'2.สมมติฐาน'!$C$6) | D12: ='2.สมมติฐาน'!$C$12*C12 | E12: 0 | F12: =MAX(F11+D12-E12,0) | G12: =F12/'2.สมมติฐาน'!$C$13 | H12: ย้อนหลังก่อน seed; ใช้ดูแนวโน้มเท่านั้น
B13: 2026 | C13: =MIN('2.สมมติฐาน'!$C$6/(1+EXP(-'2.สมมติฐาน'!$C$7*(2026-'2.สมมติฐาน'!$C$8)))*'2.สมมติฐาน'!$C$9,'2.สมมติฐาน'!$C$6) | D13: ='2.สมมติฐาน'!$C$12*C13 | E13: 0 | F13: ='2.สมมติฐาน'!$B$39 | G13: =F13/'2.สมมติฐาน'!$C$13 | H13: Seed จาก DLT BEV+PHEV สะสม
B14: 2027 | C14: =MIN('2.สมมติฐาน'!$C$6/(1+EXP(-'2.สมมติฐาน'!$C$7*(2027-'2.สมมติฐาน'!$C$8)))*'2.สมมติฐาน'!$C$9,'2.สมมติฐาน'!$C$6) | D14: ='2.สมมติฐาน'!$C$12*C14 | E14: 0 | F14: =MAX(F13+D14-E14,0) | G14: =F14/'2.สมมติฐาน'!$C$13 | H14: Forecast ต่อจาก DLT seed
B15: 2028 | C15: =MIN('2.สมมติฐาน'!$C$6/(1+EXP(-'2.สมมติฐาน'!$C$7*(2028-'2.สมมติฐาน'!$C$8)))*'2.สมมติฐาน'!$C$9,'2.สมมติฐาน'!$C$6) | D15: ='2.สมมติฐาน'!$C$12*C15 | E15: 0 | F15: =MAX(F14+D15-E15,0) | G15: =F15/'2.สมมติฐาน'!$C$13 | H15: Forecast ต่อจาก DLT seed
B16: 2029 | C16: =MIN('2.สมมติฐาน'!$C$6/(1+EXP(-'2.สมมติฐาน'!$C$7*(2029-'2.สมมติฐาน'!$C$8)))*'2.สมมติฐาน'!$C$9,'2.สมมติฐาน'!$C$6) | D16: ='2.สมมติฐาน'!$C$12*C16 | E16: 0 | F16: =MAX(F15+D16-E16,0) | G16: =F16/'2.สมมติฐาน'!$C$13 | H16: Forecast ต่อจาก DLT seed
B17: 2030 | C17: =MIN('2.สมมติฐาน'!$C$6/(1+EXP(-'2.สมมติฐาน'!$C$7*(2030-'2.สมมติฐาน'!$C$8)))*'2.สมมติฐาน'!$C$9,'2.สมมติฐาน'!$C$6) | D17: ='2.สมมติฐาน'!$C$12*C17 | E17: 0 | F17: =MAX(F16+D17-E17,0) | G17: =F17/'2.สมมติฐาน'!$C$13 | H17: Forecast ต่อจาก DLT seed
B18: 2031 | C18: =MIN('2.สมมติฐาน'!$C$6/(1+EXP(-'2.สมมติฐาน'!$C$7*(2031-'2.สมมติฐาน'!$C$8)))*'2.สมมติฐาน'!$C$9,'2.สมมติฐาน'!$C$6) | D18: ='2.สมมติฐาน'!$C$12*C18 | E18: 0 | F18: =MAX(F17+D18-E18,0) | G18: =F18/'2.สมมติฐาน'!$C$13 | H18: Forecast ต่อจาก DLT seed
B19: 2032 | C19: =MIN('2.สมมติฐาน'!$C$6/(1+EXP(-'2.สมมติฐาน'!$C$7*(2032-'2.สมมติฐาน'!$C$8)))*'2.สมมติฐาน'!$C$9,'2.สมมติฐาน'!$C$6) | D19: ='2.สมมติฐาน'!$C$12*C19 | E19: ='2.สมมติฐาน'!$C$12*C5 | F19: =MAX(F18+D19-E19,0) | G19: =F19/'2.สมมติฐาน'!$C$13 | H19: Forecast ต่อจาก DLT seed
B20: 2033 | C20: =MIN('2.สมมติฐาน'!$C$6/(1+EXP(-'2.สมมติฐาน'!$C$7*(2033-'2.สมมติฐาน'!$C$8)))*'2.สมมติฐาน'!$C$9,'2.สมมติฐาน'!$C$6) | D20: ='2.สมมติฐาน'!$C$12*C20 | E20: ='2.สมมติฐาน'!$C$12*C6 | F20: =MAX(F19+D20-E20,0) | G20: =F20/'2.สมมติฐาน'!$C$13 | H20: Forecast ต่อจาก DLT seed
B21: 2034 | C21: =MIN('2.สมมติฐาน'!$C$6/(1+EXP(-'2.สมมติฐาน'!$C$7*(2034-'2.สมมติฐาน'!$C$8)))*'2.สมมติฐาน'!$C$9,'2.สมมติฐาน'!$C$6) | D21: ='2.สมมติฐาน'!$C$12*C21 | E21: ='2.สมมติฐาน'!$C$12*C7 | F21: =MAX(F20+D21-E21,0) | G21: =F21/'2.สมมติฐาน'!$C$13 | H21: Forecast ต่อจาก DLT seed
B22: 2035 | C22: =MIN('2.สมมติฐาน'!$C$6/(1+EXP(-'2.สมมติฐาน'!$C$7*(2035-'2.สมมติฐาน'!$C$8)))*'2.สมมติฐาน'!$C$9,'2.สมมติฐาน'!$C$6) | D22: ='2.สมมติฐาน'!$C$12*C22 | E22: ='2.สมมติฐาน'!$C$12*C8 | F22: =MAX(F21+D22-E22,0) | G22: =F22/'2.สมมติฐาน'!$C$13 | H22: Forecast ต่อจาก DLT seed
B23: 2036 | C23: =MIN('2.สมมติฐาน'!$C$6/(1+EXP(-'2.สมมติฐาน'!$C$7*(2036-'2.สมมติฐาน'!$C$8)))*'2.สมมติฐาน'!$C$9,'2.สมมติฐาน'!$C$6) | D23: ='2.สมมติฐาน'!$C$12*C23 | E23: ='2.สมมติฐาน'!$C$12*C9 | F23: =MAX(F22+D23-E23,0) | G23: =F23/'2.สมมติฐาน'!$C$13 | H23: Forecast ต่อจาก DLT seed
B24: 2037 | C24: =MIN('2.สมมติฐาน'!$C$6/(1+EXP(-'2.สมมติฐาน'!$C$7*(2037-'2.สมมติฐาน'!$C$8)))*'2.สมมติฐาน'!$C$9,'2.สมมติฐาน'!$C$6) | D24: ='2.สมมติฐาน'!$C$12*C24 | E24: ='2.สมมติฐาน'!$C$12*C10 | F24: =MAX(F23+D24-E24,0) | G24: =F24/'2.สมมติฐาน'!$C$13 | H24: Forecast ต่อจาก DLT seed
B25: 2038 | C25: =MIN('2.สมมติฐาน'!$C$6/(1+EXP(-'2.สมมติฐาน'!$C$7*(2038-'2.สมมติฐาน'!$C$8)))*'2.สมมติฐาน'!$C$9,'2.สมมติฐาน'!$C$6) | D25: ='2.สมมติฐาน'!$C$12*C25 | E25: ='2.สมมติฐาน'!$C$12*C11 | F25: =MAX(F24+D25-E25,0) | G25: =F25/'2.สมมติฐาน'!$C$13 | H25: Forecast ต่อจาก DLT seed
B26: 2039 | C26: =MIN('2.สมมติฐาน'!$C$6/(1+EXP(-'2.สมมติฐาน'!$C$7*(2039-'2.สมมติฐาน'!$C$8)))*'2.สมมติฐาน'!$C$9,'2.สมมติฐาน'!$C$6) | D26: ='2.สมมติฐาน'!$C$12*C26 | E26: ='2.สมมติฐาน'!$C$12*C12 | F26: =MAX(F25+D26-E26,0) | G26: =F26/'2.สมมติฐาน'!$C$13 | H26: Forecast ต่อจาก DLT seed
B27: 2040 | C27: =MIN('2.สมมติฐาน'!$C$6/(1+EXP(-'2.สมมติฐาน'!$C$7*(2040-'2.สมมติฐาน'!$C$8)))*'2.สมมติฐาน'!$C$9,'2.สมมติฐาน'!$C$6) | D27: ='2.สมมติฐาน'!$C$12*C27 | E27: ='2.สมมติฐาน'!$C$12*C13 | F27: =MAX(F26+D27-E27,0) | G27: =F27/'2.สมมติฐาน'!$C$13 | H27: Forecast ต่อจาก DLT seed
B29: หมายเหตุ v4: ค่า 6,200 ในชีตสมมติฐานเป็น legacy placeholder สำหรับ new-car scaling เท่านั้น ไม่ใช่จำนวน BEV สะสม. ตั้งแต่ปี 2026 ตารางใช้ DLT BEV+PHEV สะสม 15,229 คันเป็น seed แล้วค่อย forecast ต่อ

Sheet 4.Demand สถานี
A1: ชั้นที่ 2 : ความต้องการสถานี (4 องค์ประกอบ)
B2: ตัวอย่างสถานี Super Hub 12 หัวชาร์จ — ใช้เพื่ออธิบาย logic ของโมเดล ไม่ใช่ผลยืนยันเชิงสถิติ
B4: ปีที่วิเคราะห์ → | C4: 2026
B6: องค์ประกอบ | C6: ครั้ง/วัน | E6: คำอธิบายสูตร
B7: EV สะสมในเชียงใหม่ (ปีที่เลือก) | C7: =INDEX('3.S-curve การยอมรับ'!F:F,MATCH(TEXT('4.Demand สถานี'!$C$4,"0"),'3.S-curve การยอมรับ'!B:B,0)) | D7: ดึงจากตาราง S-curve ตามปี
B8: 1. ผู้อยู่อาศัย (resident) | C8: =ROUND(C7*'2.สมมติฐาน'!$C$23*'2.สมมติฐาน'!$C$24/7*'2.สมมติฐาน'!$C$25,0) | D8: EV สะสม × พึ่งสาธารณะ × ครั้ง/สัปดาห์ ÷7 × capture
B9: 2. แอพเรียกรถ (ride-hail) | C9: =ROUND('2.สมมติฐาน'!$C$26*'2.สมมติฐาน'!$C$27*1*0.3,0) | D9: คนขับ × %EV × ครั้ง/วัน × capture(0.30)
B10: 3. นักท่องเที่ยว (tourist) | C10: =ROUND('2.สมมติฐาน'!$C$28*0.1*4*0.05*0.5*0.3*0.25,0) | D10: มาถึง × เช่า10% × 4วัน × EV5% × 0.5/วัน × สาธารณะ30% × capture25%
B11: 4. ขนส่ง (transit) | C11: =ROUND(20*0.25,0) | D11: EV ขนส่ง 20 × capture 0.25
B12: รวมดิบ (ก่อน calibration) | C12: =SUM(C8:C11)
B13: ครั้งชาร์จ/วัน (หลัง calibration ×0.409) | C13: =ROUND(C12*'2.สมมติฐาน'!$C$29,0)
B14: พลังงาน/วัน (kWh) | C14: =ROUND(C13*'2.สมมติฐาน'!$C$30,0)
B15: อัตราใช้งาน (12 หัว × 22 ครั้ง) | C15: =C13/(12*'2.สมมติฐาน'!$C$31)
B17: v5 recalibration: หลังใช้ DLT BEV+PHEV สะสมเป็น seed ปี 2026 raw demand ประมาณ 318 ครั้ง/วัน. ถ้ายึด anchor 130 ครั้ง/วัน factor = 130÷318 = 0.409. หากใช้ operator sensitivity 200/300 factor = 0.629/0.943 ตามลำดับ

Sheet 5.Validation
A1: ชั้นความน่าเชื่อถือ : การทวนสอบกับข้อมูลจริง
A2: เทียบโมเดลกับข้อมูลจริง พร้อมตัวชี้วัด MAPE / RMSE และสถานะ cross-validation อย่างตรงไปตรงมา
B4: A. ชั้น Adoption — S-curve เทียบยอด BEV จริง (FTI/Autolife)
B5: ปี | C5: คาดการณ์ % | D5: จริง % | E5: คลาดเคลื่อน (pp) | F5: แหล่งอ้างอิง
B6: 2566 (2023) | C6: 0.142 | D6: 0.15 | E6: =(C6-D6)*100 | F6: 76,500 คัน BEV
B7: 2567 (2024) | C7: 0.164 | D7: 0.14 | E7: =(C7-D7)*100 | F7: 70,137 คัน (เปลี่ยนเงินอุดหนุน)
B8: 2568 (2025) | C8: 0.189 | D8: 0.194 | E8: =(C8-D8)*100 | F8: 120,301 คัน (FTI เต็มปี)
B9: MAPE (เฉลี่ย % คลาดเคลื่อน) | C9: =AVERAGE(ABS(C6-D6)/D6,ABS(C7-D7)/D7,ABS(C8-D8)/D8)
B10: RMSE (pp) | C10: =SQRT(AVERAGE(E6^2,E7^2,E8^2))
B12: B. ชั้น Station — เทียบกับ temporary calibration anchor
B13: สถานี | C13: จริง (ครั้ง/วัน) | D13: โมเดล (ครั้ง/วัน) | E13: คลาดเคลื่อน | F13: แหล่ง
B14: CM Cultural Center Hub | C14: 130 | D14: 130 | E14: =ABS(D14-C14)/C14 | F14: Operator-reported / verbal anchor 2026; ยังไม่ยืนยันด้วย session log
B16: ความซื่อสัตย์ของการทวนสอบ: station layer ยังมี temporary calibration anchor 1 จุด. v5 คำนวณ factor ใหม่หลังใช้ DLT seed: raw 318 ครั้ง/วัน, anchor 130 => factor 0.409; ควรแสดง sensitivity 130/200/300 แทนการยืนยันค่าเดียว

Sheet 6.เทียบ NREL
A1: TH-EVI เทียบกับ NREL EVI-Pro
B2: หลักการบางส่วนสอดคล้องกับ NREL EVI-Pro/EVI-X แต่ TH-EVI ยังเป็น transparent screening model ที่ต้องเพิ่ม station ground truth
B4: หัวข้อ | C4: NREL EVI-Pro | D4: TH-EVI (ของเรา)
B5: แนวคิดหลัก | C5: ประมาณความต้องการโครงสร้างชาร์จจากพฤติกรรมการเดินทางของกลุ่มรถ EV | D5: ใช้แนวคิดเดียวกัน: กลุ่มรถ EV → ความต้องการชาร์จเชิงพื้นที่/เวลา
B6: ข้อมูลกองรถ | C6: ข้อมูลสำรวจการเดินทางสหรัฐ (NHTS), การจดทะเบียนรัฐ | D6: DOPA 2568, DLT เม.ย. 2569, FTI/Autolife, DOH AADT 2566; station usage ยังเป็น temporary anchor
B7: พยากรณ์การยอมรับ | C7: ฉากทัศน์ภายนอก | D7: S-curve logistic calibrate กับข้อมูล FTI รายปี (MAPE 8.5%)
B8: ปริมาณจราจร | C8: แบบจำลองการเดินทางระดับเขต | D8: AADT จริงจากกรมทางหลวง (DOH) รายเส้นทาง
B9: การจัดคิว/หัวชาร์จ | C9: จำลองพฤติกรรมการเสียบชาร์จ | D9: Erlang-C คิดระดับบริการ (P(wait)≤10%, รอ<10 นาที)
B10: การปรับเทียบ | C10: calibrate กับข้อมูลใช้งานจริงขนาดใหญ่ | D10: temporary calibration factor ที่ rebased จาก DLT seed: 0.409 สำหรับ anchor 130; sensitivity 0.629/0.943 สำหรับ 200/300; แผนขยายเป็น LOO CV เมื่อมี session log หลายสถานี
B11: ความโปร่งใส | C11: เอกสารวิชาการ + เครื่องมือ | D11: ทุกสมมติฐานเปิดในชีตเดียว แก้แล้วทั้งโมเดลอัปเดต
B13: สรุป: TH-EVI เป็น NREL-inspired transparent screening model ไม่ใช่ NREL full simulation. ชั้น public data (DOPA/DLT/AADT) ได้ verify แล้วใน v3; ชั้น station calibration ยังต้องเพิ่มข้อมูลจริงเพื่อยืนยันความแม่นยำ

Sheet 7.Data Verification
A1: หมวด | B1: รายการ | C1: ค่า | D1: หน่วย | E1: แหล่งที่มา | F1: สถานะ | G1: หมายเหตุ
A2: DOPA | B2: ประชากรจังหวัดเชียงใหม่ | C2: 1798588 | D2: คน | E2: DOPA 2568 | F2: Verified | G2: ครัวเรือน 916,688
A3: DLT | B3: รย.1 รถยนต์นั่งรวม | C3: 453310 | D3: คัน | E3: DLT 30 เม.ย. 2569 | F3: Verified | G3: denominator หลักสำหรับ passenger-car EV share
A4: DLT | B4: รย.1 BEV | C4: 13089 | D4: คัน | E4: DLT 30 เม.ย. 2569 | F4: Verified | G4: BEV share 2.89%
A5: DLT | B5: รย.1 PHEV | C5: 2140 | D5: คัน | E5: DLT 30 เม.ย. 2569 | F5: Verified | G5: PHEV gasoline + PHEV diesel
A6: DLT | B6: รย.1 BEV+PHEV | C6: 15229 | D6: คัน | E6: DLT 30 เม.ย. 2569 | F6: Verified | G6: chargeable EV stock = 3.36% ของ รย.1
A7: DLT | B7: รถตามกฎหมายรถยนต์ BEV+PHEV | C7: 18189 | D7: คัน | E7: DLT 30 เม.ย. 2569 | F7: Verified | G7: ภาพรวมรถตามกฎหมายว่าด้วยรถยนต์
A8: AADT | B8: Route 1141 ดอนจั่น-เชียงใหม่ 7+000 | C8: 118853 | D8: คัน/วัน | E8: DOH AADT 2566 | F8: Verified | G8: ค่าสูงสุดในเชียงใหม่ชุดปัจจุบัน
A9: AADT | B9: Route 118 เชียงใหม่-ดอยนางแก้ว 0+500 | C9: 78356 | D9: คัน/วัน | E9: DOH AADT 2566 | F9: Verified | G9: corridor เชียงใหม่-เชียงราย
A10: AADT | B10: Route 11 อุโมงค์-รินคำ 543+850 | C10: 69988 | D10: คัน/วัน | E10: DOH AADT 2566 | F10: Verified | G10: urban/corridor core
A11: AADT | B11: Route 108 เชียงใหม่-ปากทางท่าลี่ 7+650 | C11: 60644 | D11: คัน/วัน | E11: DOH AADT 2566 | F11: Verified | G11: south/west corridor
A12: Station | B12: CM Cultural Center anchor | C12: 130 / 200-300 sensitivity | D12: ครั้ง/วัน | E12: operator-reported/verbal | F12: Unverified | G12: ไม่ควรใช้เป็น ground truth จนกว่าจะได้ log จริง

Sheet 8.Reviewer Notes
A1: ระดับ | B1: ประเด็น | C1: คำแนะนำ
A2: สำคัญมาก | B2: 130 ครั้ง/วัน ยังไม่ใช่ ground truth | C2: ให้เรียกว่า temporary calibration anchor และทำ sensitivity 130 / 200 / 300 ครั้งต่อวัน ก่อนให้ที่ปรึกษาปรับโมเดล
A3: สำคัญมาก | B3: Station validation ยัง just-identified | C3: มีข้อมูลสถานี 1 จุดและ calibration factor 1 ตัว จึง fit ได้พอดีแต่ยังวัดความแม่นนอกตัวอย่างไม่ได้
A4: สำคัญ | B4: ประโยค 'ทุกตัวเลขมาจากแหล่งเปิดที่ตรวจสอบได้' overclaim | C4: ควรแยก public reference data กับ operator-reported/unverified station data
A5: สำคัญ | B5: S-curve ย้อนหลังทำให้ปี 2018-2022 มี BEV share สูงเกินจริง | C5: ควรพิจารณาเริ่มสะสม EV จากปีที่มีข้อมูลจริง หรือ seed ด้วย DLT BEV stock แล้ว forecast ต่อ
A6: กลาง | B6: Scrappage wording ไม่ตรงกับสูตร | C6: สูตรเป็น cohort retirement หลัง 14 ปี ไม่ใช่ linear scrappage; ให้แก้คำหรือปรับสูตร
A7: กลาง | B7: NREL wording | C7: ใช้คำว่า NREL-inspired / EVI-Pro/EVI-X screening model ไม่ควรสื่อว่าเทียบเท่า NREL full simulation
A8: ควรเพิ่ม | B8: Sensitivity sheet | C8: เพิ่มตารางผล station demand เมื่อ anchor = 130, 200, 300 เพื่อให้ที่ปรึกษาเห็นผลของ calibration uncertainty
A9: แก้แล้วใน v3 | B9: DLT/DOPA/AADT verified sheet | C9: เพิ่มชีต 7.Data Verification และแก้ passenger fleet เชียงใหม่จาก 350,000 เป็น DLT รย.1 453,310 คัน
A10: แก้แล้วใน v3 | B10: Station anchor wording | C10: ระบุว่า 130 ครั้ง/วันยังไม่ยืนยัน และควรทำ sensitivity 130/200/300
A11: แก้แล้วใน v4 | B11: S-curve ใช้ DLT stock เป็น seed | C11: ปี 2026 ในตาราง adoption ถูกตรึงด้วย DLT BEV+PHEV 15,229 คัน; ค่า 6,200 เหลือเป็น legacy placeholder สำหรับ new-car scaling
A12: แก้แล้วใน v5 | B12: Rebase calibration factor หลังใช้ DLT seed | C12: ค่า 0.657 มาจากโมเดลก่อนใช้ DLT seed. v5 ปรับเป็น 0.409 สำหรับ anchor 130 จาก raw demand 318 ครั้ง/วัน และเพิ่ม sensitivity 200/300
